{
 "cells": [
  {
   "cell_type": "code",
   "execution_count": 2,
   "metadata": {},
   "outputs": [],
   "source": [
    "#import dataset\n",
    "\n",
    "import tensorflow as tf \n",
    "import tensorflow_datasets as tfds"
   ]
  },
  {
   "cell_type": "code",
   "execution_count": 5,
   "metadata": {},
   "outputs": [
    {
     "ename": "AssertionError",
     "evalue": "Dataset imdb_reviews: could not find data in C:\\Users\\ASUS\\tensorflow_datasets. Please make sure to call dataset_builder.download_and_prepare(), or pass download=True to tfds.load() before trying to access the tf.data.Dataset object.",
     "output_type": "error",
     "traceback": [
      "\u001b[1;31m---------------------------------------------------------------------------\u001b[0m",
      "\u001b[1;31mAssertionError\u001b[0m                            Traceback (most recent call last)",
      "Cell \u001b[1;32mIn[5], line 1\u001b[0m\n\u001b[1;32m----> 1\u001b[0m imdb, info \u001b[38;5;241m=\u001b[39m \u001b[43mtfds\u001b[49m\u001b[38;5;241;43m.\u001b[39;49m\u001b[43mload\u001b[49m\u001b[43m(\u001b[49m\u001b[38;5;124;43m\"\u001b[39;49m\u001b[38;5;124;43mimdb_reviews\u001b[39;49m\u001b[38;5;124;43m\"\u001b[39;49m\u001b[43m,\u001b[49m\u001b[43m \u001b[49m\u001b[43mwith_info\u001b[49m\u001b[38;5;241;43m=\u001b[39;49m\u001b[38;5;28;43;01mTrue\u001b[39;49;00m\u001b[43m,\u001b[49m\u001b[43m \u001b[49m\u001b[43mas_supervised\u001b[49m\u001b[38;5;241;43m=\u001b[39;49m\u001b[38;5;28;43;01mTrue\u001b[39;49;00m\u001b[43m,\u001b[49m\u001b[43m \u001b[49m\u001b[43mdownload\u001b[49m\u001b[38;5;241;43m=\u001b[39;49m\u001b[38;5;28;43;01mFalse\u001b[39;49;00m\u001b[43m)\u001b[49m\n",
      "File \u001b[1;32mc:\\Users\\ASUS\\AppData\\Local\\Programs\\Python\\Python312\\Lib\\site-packages\\tensorflow_datasets\\core\\logging\\__init__.py:176\u001b[0m, in \u001b[0;36m_FunctionDecorator.__call__\u001b[1;34m(self, function, instance, args, kwargs)\u001b[0m\n\u001b[0;32m    174\u001b[0m metadata \u001b[38;5;241m=\u001b[39m \u001b[38;5;28mself\u001b[39m\u001b[38;5;241m.\u001b[39m_start_call()\n\u001b[0;32m    175\u001b[0m \u001b[38;5;28;01mtry\u001b[39;00m:\n\u001b[1;32m--> 176\u001b[0m   \u001b[38;5;28;01mreturn\u001b[39;00m \u001b[43mfunction\u001b[49m\u001b[43m(\u001b[49m\u001b[38;5;241;43m*\u001b[39;49m\u001b[43margs\u001b[49m\u001b[43m,\u001b[49m\u001b[43m \u001b[49m\u001b[38;5;241;43m*\u001b[39;49m\u001b[38;5;241;43m*\u001b[39;49m\u001b[43mkwargs\u001b[49m\u001b[43m)\u001b[49m\n\u001b[0;32m    177\u001b[0m \u001b[38;5;28;01mexcept\u001b[39;00m \u001b[38;5;167;01mException\u001b[39;00m:\n\u001b[0;32m    178\u001b[0m   metadata\u001b[38;5;241m.\u001b[39mmark_error()\n",
      "File \u001b[1;32mc:\\Users\\ASUS\\AppData\\Local\\Programs\\Python\\Python312\\Lib\\site-packages\\tensorflow_datasets\\core\\load.py:673\u001b[0m, in \u001b[0;36mload\u001b[1;34m(name, split, data_dir, batch_size, shuffle_files, download, as_supervised, decoders, read_config, with_info, builder_kwargs, download_and_prepare_kwargs, as_dataset_kwargs, try_gcs)\u001b[0m\n\u001b[0;32m    670\u001b[0m as_dataset_kwargs\u001b[38;5;241m.\u001b[39msetdefault(\u001b[38;5;124m'\u001b[39m\u001b[38;5;124mshuffle_files\u001b[39m\u001b[38;5;124m'\u001b[39m, shuffle_files)\n\u001b[0;32m    671\u001b[0m as_dataset_kwargs\u001b[38;5;241m.\u001b[39msetdefault(\u001b[38;5;124m'\u001b[39m\u001b[38;5;124mread_config\u001b[39m\u001b[38;5;124m'\u001b[39m, read_config)\n\u001b[1;32m--> 673\u001b[0m ds \u001b[38;5;241m=\u001b[39m \u001b[43mdbuilder\u001b[49m\u001b[38;5;241;43m.\u001b[39;49m\u001b[43mas_dataset\u001b[49m\u001b[43m(\u001b[49m\u001b[38;5;241;43m*\u001b[39;49m\u001b[38;5;241;43m*\u001b[39;49m\u001b[43mas_dataset_kwargs\u001b[49m\u001b[43m)\u001b[49m\n\u001b[0;32m    674\u001b[0m \u001b[38;5;28;01mif\u001b[39;00m with_info:\n\u001b[0;32m    675\u001b[0m   \u001b[38;5;28;01mreturn\u001b[39;00m ds, dbuilder\u001b[38;5;241m.\u001b[39minfo\n",
      "File \u001b[1;32mc:\\Users\\ASUS\\AppData\\Local\\Programs\\Python\\Python312\\Lib\\site-packages\\tensorflow_datasets\\core\\logging\\__init__.py:176\u001b[0m, in \u001b[0;36m_FunctionDecorator.__call__\u001b[1;34m(self, function, instance, args, kwargs)\u001b[0m\n\u001b[0;32m    174\u001b[0m metadata \u001b[38;5;241m=\u001b[39m \u001b[38;5;28mself\u001b[39m\u001b[38;5;241m.\u001b[39m_start_call()\n\u001b[0;32m    175\u001b[0m \u001b[38;5;28;01mtry\u001b[39;00m:\n\u001b[1;32m--> 176\u001b[0m   \u001b[38;5;28;01mreturn\u001b[39;00m \u001b[43mfunction\u001b[49m\u001b[43m(\u001b[49m\u001b[38;5;241;43m*\u001b[39;49m\u001b[43margs\u001b[49m\u001b[43m,\u001b[49m\u001b[43m \u001b[49m\u001b[38;5;241;43m*\u001b[39;49m\u001b[38;5;241;43m*\u001b[39;49m\u001b[43mkwargs\u001b[49m\u001b[43m)\u001b[49m\n\u001b[0;32m    177\u001b[0m \u001b[38;5;28;01mexcept\u001b[39;00m \u001b[38;5;167;01mException\u001b[39;00m:\n\u001b[0;32m    178\u001b[0m   metadata\u001b[38;5;241m.\u001b[39mmark_error()\n",
      "File \u001b[1;32mc:\\Users\\ASUS\\AppData\\Local\\Programs\\Python\\Python312\\Lib\\site-packages\\tensorflow_datasets\\core\\dataset_builder.py:1004\u001b[0m, in \u001b[0;36mDatasetBuilder.as_dataset\u001b[1;34m(self, split, batch_size, shuffle_files, decoders, read_config, as_supervised)\u001b[0m\n\u001b[0;32m   1002\u001b[0m \u001b[38;5;66;03m# pylint: enable=line-too-long\u001b[39;00m\n\u001b[0;32m   1003\u001b[0m \u001b[38;5;28;01mif\u001b[39;00m \u001b[38;5;129;01mnot\u001b[39;00m \u001b[38;5;28mself\u001b[39m\u001b[38;5;241m.\u001b[39mdata_path\u001b[38;5;241m.\u001b[39mexists():\n\u001b[1;32m-> 1004\u001b[0m   \u001b[38;5;28;01mraise\u001b[39;00m \u001b[38;5;167;01mAssertionError\u001b[39;00m(\n\u001b[0;32m   1005\u001b[0m       \u001b[38;5;124m\"\u001b[39m\u001b[38;5;124mDataset \u001b[39m\u001b[38;5;132;01m%s\u001b[39;00m\u001b[38;5;124m: could not find data in \u001b[39m\u001b[38;5;132;01m%s\u001b[39;00m\u001b[38;5;124m. Please make sure to call \u001b[39m\u001b[38;5;124m\"\u001b[39m\n\u001b[0;32m   1006\u001b[0m       \u001b[38;5;124m\"\u001b[39m\u001b[38;5;124mdataset_builder.download_and_prepare(), or pass download=True to \u001b[39m\u001b[38;5;124m\"\u001b[39m\n\u001b[0;32m   1007\u001b[0m       \u001b[38;5;124m\"\u001b[39m\u001b[38;5;124mtfds.load() before trying to access the tf.data.Dataset object.\u001b[39m\u001b[38;5;124m\"\u001b[39m\n\u001b[0;32m   1008\u001b[0m       \u001b[38;5;241m%\u001b[39m (\u001b[38;5;28mself\u001b[39m\u001b[38;5;241m.\u001b[39mname, \u001b[38;5;28mself\u001b[39m\u001b[38;5;241m.\u001b[39mdata_dir_root)\n\u001b[0;32m   1009\u001b[0m   )\n\u001b[0;32m   1011\u001b[0m \u001b[38;5;66;03m# By default, return all splits\u001b[39;00m\n\u001b[0;32m   1012\u001b[0m \u001b[38;5;28;01mif\u001b[39;00m split \u001b[38;5;129;01mis\u001b[39;00m \u001b[38;5;28;01mNone\u001b[39;00m:\n",
      "\u001b[1;31mAssertionError\u001b[0m: Dataset imdb_reviews: could not find data in C:\\Users\\ASUS\\tensorflow_datasets. Please make sure to call dataset_builder.download_and_prepare(), or pass download=True to tfds.load() before trying to access the tf.data.Dataset object."
     ]
    }
   ],
   "source": [
    "imdb, info = tfds.load(\"imdb_reviews\", with_info=True, as_supervised=True, download=False)"
   ]
  },
  {
   "cell_type": "code",
   "execution_count": null,
   "metadata": {},
   "outputs": [],
   "source": []
  },
  {
   "cell_type": "code",
   "execution_count": null,
   "metadata": {},
   "outputs": [],
   "source": []
  }
 ],
 "metadata": {
  "kernelspec": {
   "display_name": "Python 3",
   "language": "python",
   "name": "python3"
  },
  "language_info": {
   "codemirror_mode": {
    "name": "ipython",
    "version": 3
   },
   "file_extension": ".py",
   "mimetype": "text/x-python",
   "name": "python",
   "nbconvert_exporter": "python",
   "pygments_lexer": "ipython3",
   "version": "3.12.2"
  }
 },
 "nbformat": 4,
 "nbformat_minor": 2
}
